<!-- Generated by scripts/build_wormbody_v2.py. 95-muscle innervation lives in motor_innervation.json. -->
<mujoco model="c_elegans_wormbody_v2">
  <compiler angle="radian" autolimits="true"/>
  <option timestep="0.0005" integrator="implicitfast" viscosity="1.0e-3" density="1000"/>
  <visual>
    <headlight diffuse="0.8 0.8 0.8" ambient="0.3 0.3 0.3" specular="0.2 0.2 0.2"/>
    <global offwidth="1200" offheight="800"/>
  </visual>
  <default>
    <joint damping="0.5" stiffness="0.0" limited="true" range="-0.5 0.5"/>
    <geom density="1000" friction="0.5 0.1 0.01"/>
    <position ctrllimited="true" ctrlrange="-0.5 0.5" kp="60.0" kv="2.0"/>
  </default>
  <worldbody>
    <geom name="substrate" type="plane" size="0.01 0.01 0.001" rgba="0.95 0.92 0.82 1"/>
    <light name="overhead" pos="0 0 0.02" dir="0 0 -1" diffuse="0.8 0.8 0.8"/>
    <body name="segment_0" pos="0 0 0.0800000" euler="0 0 0">
      <freejoint name="root"/>
      <geom name="geom_0" type="capsule" fromto="0 0 0 0.0500000 0 0" size="0.0400000" rgba="0.25 0.38 0.25 1"/>
      <site name="s0_DL" pos="0.025000 0.028000 0.028000" size="0.002"/>
      <site name="s0_DR" pos="0.025000 -0.028000 0.028000" size="0.002"/>
      <site name="s0_VL" pos="0.025000 0.028000 -0.028000" size="0.002"/>
      <site name="s0_VR" pos="0.025000 -0.028000 -0.028000" size="0.002"/>
      <body name="segment_1" pos="0.0500000 0 0">
        <joint name="hinge_1" type="hinge" axis="0 0 1"/>
        <geom name="geom_1" type="capsule" fromto="0 0 0 0.0500000 0 0" size="0.0400000" rgba="0.27 0.39 0.25 1"/>
        <site name="s1_DL" pos="0.025000 0.028000 0.028000" size="0.002"/>
        <site name="s1_DR" pos="0.025000 -0.028000 0.028000" size="0.002"/>
        <site name="s1_VL" pos="0.025000 0.028000 -0.028000" size="0.002"/>
        <site name="s1_VR" pos="0.025000 -0.028000 -0.028000" size="0.002"/>
        <body name="segment_2" pos="0.0500000 0 0">
          <joint name="hinge_2" type="hinge" axis="0 0 1"/>
          <geom name="geom_2" type="capsule" fromto="0 0 0 0.0500000 0 0" size="0.0400000" rgba="0.29 0.40 0.25 1"/>
          <site name="s2_DL" pos="0.025000 0.028000 0.028000" size="0.002"/>
          <site name="s2_DR" pos="0.025000 -0.028000 0.028000" size="0.002"/>
          <site name="s2_VL" pos="0.025000 0.028000 -0.028000" size="0.002"/>
          <site name="s2_VR" pos="0.025000 -0.028000 -0.028000" size="0.002"/>
          <body name="segment_3" pos="0.0500000 0 0">
            <joint name="hinge_3" type="hinge" axis="0 0 1"/>
            <geom name="geom_3" type="capsule" fromto="0 0 0 0.0500000 0 0" size="0.0400000" rgba="0.31 0.41 0.25 1"/>
            <site name="s3_DL" pos="0.025000 0.028000 0.028000" size="0.002"/>
            <site name="s3_DR" pos="0.025000 -0.028000 0.028000" size="0.002"/>
            <site name="s3_VL" pos="0.025000 0.028000 -0.028000" size="0.002"/>
            <site name="s3_VR" pos="0.025000 -0.028000 -0.028000" size="0.002"/>
            <body name="segment_4" pos="0.0500000 0 0">
              <joint name="hinge_4" type="hinge" axis="0 0 1"/>
              <geom name="geom_4" type="capsule" fromto="0 0 0 0.0500000 0 0" size="0.0400000" rgba="0.33 0.42 0.25 1"/>
              <site name="s4_DL" pos="0.025000 0.028000 0.028000" size="0.002"/>
              <site name="s4_DR" pos="0.025000 -0.028000 0.028000" size="0.002"/>
              <site name="s4_VL" pos="0.025000 0.028000 -0.028000" size="0.002"/>
              <site name="s4_VR" pos="0.025000 -0.028000 -0.028000" size="0.002"/>
              <body name="segment_5" pos="0.0500000 0 0">
                <joint name="hinge_5" type="hinge" axis="0 0 1"/>
                <geom name="geom_5" type="capsule" fromto="0 0 0 0.0500000 0 0" size="0.0400000" rgba="0.35 0.43 0.25 1"/>
                <site name="s5_DL" pos="0.025000 0.028000 0.028000" size="0.002"/>
                <site name="s5_DR" pos="0.025000 -0.028000 0.028000" size="0.002"/>
                <site name="s5_VL" pos="0.025000 0.028000 -0.028000" size="0.002"/>
                <site name="s5_VR" pos="0.025000 -0.028000 -0.028000" size="0.002"/>
                <body name="segment_6" pos="0.0500000 0 0">
                  <joint name="hinge_6" type="hinge" axis="0 0 1"/>
                  <geom name="geom_6" type="capsule" fromto="0 0 0 0.0500000 0 0" size="0.0400000" rgba="0.37 0.44 0.25 1"/>
                  <site name="s6_DL" pos="0.025000 0.028000 0.028000" size="0.002"/>
                  <site name="s6_DR" pos="0.025000 -0.028000 0.028000" size="0.002"/>
                  <site name="s6_VL" pos="0.025000 0.028000 -0.028000" size="0.002"/>
                  <site name="s6_VR" pos="0.025000 -0.028000 -0.028000" size="0.002"/>
                  <body name="segment_7" pos="0.0500000 0 0">
                    <joint name="hinge_7" type="hinge" axis="0 0 1"/>
                    <geom name="geom_7" type="capsule" fromto="0 0 0 0.0500000 0 0" size="0.0400000" rgba="0.39 0.45 0.25 1"/>
                    <site name="s7_DL" pos="0.025000 0.028000 0.028000" size="0.002"/>
                    <site name="s7_DR" pos="0.025000 -0.028000 0.028000" size="0.002"/>
                    <site name="s7_VL" pos="0.025000 0.028000 -0.028000" size="0.002"/>
                    <site name="s7_VR" pos="0.025000 -0.028000 -0.028000" size="0.002"/>
                    <body name="segment_8" pos="0.0500000 0 0">
                      <joint name="hinge_8" type="hinge" axis="0 0 1"/>
                      <geom name="geom_8" type="capsule" fromto="0 0 0 0.0500000 0 0" size="0.0400000" rgba="0.41 0.46 0.25 1"/>
                      <site name="s8_DL" pos="0.025000 0.028000 0.028000" size="0.002"/>
                      <site name="s8_DR" pos="0.025000 -0.028000 0.028000" size="0.002"/>
                      <site name="s8_VL" pos="0.025000 0.028000 -0.028000" size="0.002"/>
                      <site name="s8_VR" pos="0.025000 -0.028000 -0.028000" size="0.002"/>
                      <body name="segment_9" pos="0.0500000 0 0">
                        <joint name="hinge_9" type="hinge" axis="0 0 1"/>
                        <geom name="geom_9" type="capsule" fromto="0 0 0 0.0500000 0 0" size="0.0400000" rgba="0.43 0.47 0.25 1"/>
                        <site name="s9_DL" pos="0.025000 0.028000 0.028000" size="0.002"/>
                        <site name="s9_DR" pos="0.025000 -0.028000 0.028000" size="0.002"/>
                        <site name="s9_VL" pos="0.025000 0.028000 -0.028000" size="0.002"/>
                        <site name="s9_VR" pos="0.025000 -0.028000 -0.028000" size="0.002"/>
                        <body name="segment_10" pos="0.0500000 0 0">
                          <joint name="hinge_10" type="hinge" axis="0 0 1"/>
                          <geom name="geom_10" type="capsule" fromto="0 0 0 0.0500000 0 0" size="0.0400000" rgba="0.45 0.48 0.25 1"/>
                          <site name="s10_DL" pos="0.025000 0.028000 0.028000" size="0.002"/>
                          <site name="s10_DR" pos="0.025000 -0.028000 0.028000" size="0.002"/>
                          <site name="s10_VL" pos="0.025000 0.028000 -0.028000" size="0.002"/>
                          <site name="s10_VR" pos="0.025000 -0.028000 -0.028000" size="0.002"/>
                          <body name="segment_11" pos="0.0500000 0 0">
                            <joint name="hinge_11" type="hinge" axis="0 0 1"/>
                            <geom name="geom_11" type="capsule" fromto="0 0 0 0.0500000 0 0" size="0.0400000" rgba="0.47 0.49 0.25 1"/>
                            <site name="s11_DL" pos="0.025000 0.028000 0.028000" size="0.002"/>
                            <site name="s11_DR" pos="0.025000 -0.028000 0.028000" size="0.002"/>
                            <site name="s11_VL" pos="0.025000 0.028000 -0.028000" size="0.002"/>
                            <site name="s11_VR" pos="0.025000 -0.028000 -0.028000" size="0.002"/>
                            <body name="segment_12" pos="0.0500000 0 0">
                              <joint name="hinge_12" type="hinge" axis="0 0 1"/>
                              <geom name="geom_12" type="capsule" fromto="0 0 0 0.0500000 0 0" size="0.0400000" rgba="0.49 0.50 0.25 1"/>
                              <site name="s12_DL" pos="0.025000 0.028000 0.028000" size="0.002"/>
                              <site name="s12_DR" pos="0.025000 -0.028000 0.028000" size="0.002"/>
                              <site name="s12_VL" pos="0.025000 0.028000 -0.028000" size="0.002"/>
                              <site name="s12_VR" pos="0.025000 -0.028000 -0.028000" size="0.002"/>
                              <body name="segment_13" pos="0.0500000 0 0">
                                <joint name="hinge_13" type="hinge" axis="0 0 1"/>
                                <geom name="geom_13" type="capsule" fromto="0 0 0 0.0500000 0 0" size="0.0400000" rgba="0.51 0.51 0.25 1"/>
                                <site name="s13_DL" pos="0.025000 0.028000 0.028000" size="0.002"/>
                                <site name="s13_DR" pos="0.025000 -0.028000 0.028000" size="0.002"/>
                                <site name="s13_VL" pos="0.025000 0.028000 -0.028000" size="0.002"/>
                                <site name="s13_VR" pos="0.025000 -0.028000 -0.028000" size="0.002"/>
                                <body name="segment_14" pos="0.0500000 0 0">
                                  <joint name="hinge_14" type="hinge" axis="0 0 1"/>
                                  <geom name="geom_14" type="capsule" fromto="0 0 0 0.0500000 0 0" size="0.0400000" rgba="0.53 0.52 0.25 1"/>
                                  <site name="s14_DL" pos="0.025000 0.028000 0.028000" size="0.002"/>
                                  <site name="s14_DR" pos="0.025000 -0.028000 0.028000" size="0.002"/>
                                  <site name="s14_VL" pos="0.025000 0.028000 -0.028000" size="0.002"/>
                                  <site name="s14_VR" pos="0.025000 -0.028000 -0.028000" size="0.002"/>
                                  <body name="segment_15" pos="0.0500000 0 0">
                                    <joint name="hinge_15" type="hinge" axis="0 0 1"/>
                                    <geom name="geom_15" type="capsule" fromto="0 0 0 0.0500000 0 0" size="0.0400000" rgba="0.55 0.53 0.25 1"/>
                                    <site name="s15_DL" pos="0.025000 0.028000 0.028000" size="0.002"/>
                                    <site name="s15_DR" pos="0.025000 -0.028000 0.028000" size="0.002"/>
                                    <site name="s15_VL" pos="0.025000 0.028000 -0.028000" size="0.002"/>
                                    <site name="s15_VR" pos="0.025000 -0.028000 -0.028000" size="0.002"/>
                                    <body name="segment_16" pos="0.0500000 0 0">
                                      <joint name="hinge_16" type="hinge" axis="0 0 1"/>
                                      <geom name="geom_16" type="capsule" fromto="0 0 0 0.0500000 0 0" size="0.0400000" rgba="0.57 0.54 0.25 1"/>
                                      <site name="s16_DL" pos="0.025000 0.028000 0.028000" size="0.002"/>
                                      <site name="s16_DR" pos="0.025000 -0.028000 0.028000" size="0.002"/>
                                      <site name="s16_VL" pos="0.025000 0.028000 -0.028000" size="0.002"/>
                                      <site name="s16_VR" pos="0.025000 -0.028000 -0.028000" size="0.002"/>
                                      <body name="segment_17" pos="0.0500000 0 0">
                                        <joint name="hinge_17" type="hinge" axis="0 0 1"/>
                                        <geom name="geom_17" type="capsule" fromto="0 0 0 0.0500000 0 0" size="0.0400000" rgba="0.59 0.55 0.25 1"/>
                                        <site name="s17_DL" pos="0.025000 0.028000 0.028000" size="0.002"/>
                                        <site name="s17_DR" pos="0.025000 -0.028000 0.028000" size="0.002"/>
                                        <site name="s17_VL" pos="0.025000 0.028000 -0.028000" size="0.002"/>
                                        <site name="s17_VR" pos="0.025000 -0.028000 -0.028000" size="0.002"/>
                                        <body name="segment_18" pos="0.0500000 0 0">
                                          <joint name="hinge_18" type="hinge" axis="0 0 1"/>
                                          <geom name="geom_18" type="capsule" fromto="0 0 0 0.0500000 0 0" size="0.0400000" rgba="0.61 0.56 0.25 1"/>
                                          <site name="s18_DL" pos="0.025000 0.028000 0.028000" size="0.002"/>
                                          <site name="s18_DR" pos="0.025000 -0.028000 0.028000" size="0.002"/>
                                          <site name="s18_VL" pos="0.025000 0.028000 -0.028000" size="0.002"/>
                                          <site name="s18_VR" pos="0.025000 -0.028000 -0.028000" size="0.002"/>
                                          <body name="segment_19" pos="0.0500000 0 0">
                                            <joint name="hinge_19" type="hinge" axis="0 0 1"/>
                                            <geom name="geom_19" type="capsule" fromto="0 0 0 0.0500000 0 0" size="0.0400000" rgba="0.63 0.57 0.25 1"/>
                                            <site name="s19_DL" pos="0.025000 0.028000 0.028000" size="0.002"/>
                                            <site name="s19_DR" pos="0.025000 -0.028000 0.028000" size="0.002"/>
                                            <site name="s19_VL" pos="0.025000 0.028000 -0.028000" size="0.002"/>
                                            <site name="s19_VR" pos="0.025000 -0.028000 -0.028000" size="0.002"/>
                                          </body>
                                        </body>
                                      </body>
                                    </body>
                                  </body>
                                </body>
                              </body>
                            </body>
                          </body>
                        </body>
                      </body>
                    </body>
                  </body>
                </body>
              </body>
            </body>
          </body>
        </body>
      </body>
    </body>
  </worldbody>
  <actuator>
    <position name="act_hinge_1" joint="hinge_1" kp="60.0"/>
    <position name="act_hinge_2" joint="hinge_2" kp="60.0"/>
    <position name="act_hinge_3" joint="hinge_3" kp="60.0"/>
    <position name="act_hinge_4" joint="hinge_4" kp="60.0"/>
    <position name="act_hinge_5" joint="hinge_5" kp="60.0"/>
    <position name="act_hinge_6" joint="hinge_6" kp="60.0"/>
    <position name="act_hinge_7" joint="hinge_7" kp="60.0"/>
    <position name="act_hinge_8" joint="hinge_8" kp="60.0"/>
    <position name="act_hinge_9" joint="hinge_9" kp="60.0"/>
    <position name="act_hinge_10" joint="hinge_10" kp="60.0"/>
    <position name="act_hinge_11" joint="hinge_11" kp="60.0"/>
    <position name="act_hinge_12" joint="hinge_12" kp="60.0"/>
    <position name="act_hinge_13" joint="hinge_13" kp="60.0"/>
    <position name="act_hinge_14" joint="hinge_14" kp="60.0"/>
    <position name="act_hinge_15" joint="hinge_15" kp="60.0"/>
    <position name="act_hinge_16" joint="hinge_16" kp="60.0"/>
    <position name="act_hinge_17" joint="hinge_17" kp="60.0"/>
    <position name="act_hinge_18" joint="hinge_18" kp="60.0"/>
    <position name="act_hinge_19" joint="hinge_19" kp="60.0"/>
    <position name="muscle_0_DL" joint="hinge_1" kp="40.0" ctrlrange="-0.5 0.5"/>
    <position name="muscle_0_DR" joint="hinge_1" kp="40.0" ctrlrange="-0.5 0.5"/>
    <position name="muscle_0_VL" joint="hinge_1" kp="40.0" ctrlrange="-0.5 0.5"/>
    <position name="muscle_0_VR" joint="hinge_1" kp="40.0" ctrlrange="-0.5 0.5"/>
    <position name="muscle_1_DL" joint="hinge_1" kp="40.0" ctrlrange="-0.5 0.5"/>
    <position name="muscle_1_DR" joint="hinge_1" kp="40.0" ctrlrange="-0.5 0.5"/>
    <position name="muscle_1_VL" joint="hinge_1" kp="40.0" ctrlrange="-0.5 0.5"/>
    <position name="muscle_1_VR" joint="hinge_1" kp="40.0" ctrlrange="-0.5 0.5"/>
    <position name="muscle_2_DL" joint="hinge_2" kp="40.0" ctrlrange="-0.5 0.5"/>
    <position name="muscle_2_DR" joint="hinge_2" kp="40.0" ctrlrange="-0.5 0.5"/>
    <position name="muscle_2_VL" joint="hinge_2" kp="40.0" ctrlrange="-0.5 0.5"/>
    <position name="muscle_2_VR" joint="hinge_2" kp="40.0" ctrlrange="-0.5 0.5"/>
    <position name="muscle_3_DL" joint="hinge_3" kp="40.0" ctrlrange="-0.5 0.5"/>
    <position name="muscle_3_DR" joint="hinge_3" kp="40.0" ctrlrange="-0.5 0.5"/>
    <position name="muscle_3_VL" joint="hinge_3" kp="40.0" ctrlrange="-0.5 0.5"/>
    <position name="muscle_3_VR" joint="hinge_3" kp="40.0" ctrlrange="-0.5 0.5"/>
    <position name="muscle_4_DL" joint="hinge_4" kp="40.0" ctrlrange="-0.5 0.5"/>
    <position name="muscle_4_DR" joint="hinge_4" kp="40.0" ctrlrange="-0.5 0.5"/>
    <position name="muscle_4_VL" joint="hinge_4" kp="40.0" ctrlrange="-0.5 0.5"/>
    <position name="muscle_4_VR" joint="hinge_4" kp="40.0" ctrlrange="-0.5 0.5"/>
    <position name="muscle_5_DL" joint="hinge_5" kp="40.0" ctrlrange="-0.5 0.5"/>
    <position name="muscle_5_DR" joint="hinge_5" kp="40.0" ctrlrange="-0.5 0.5"/>
    <position name="muscle_5_VL" joint="hinge_5" kp="40.0" ctrlrange="-0.5 0.5"/>
    <position name="muscle_5_VR" joint="hinge_5" kp="40.0" ctrlrange="-0.5 0.5"/>
    <position name="muscle_6_DL" joint="hinge_6" kp="40.0" ctrlrange="-0.5 0.5"/>
    <position name="muscle_6_DR" joint="hinge_6" kp="40.0" ctrlrange="-0.5 0.5"/>
    <position name="muscle_6_VL" joint="hinge_6" kp="40.0" ctrlrange="-0.5 0.5"/>
    <position name="muscle_6_VR" joint="hinge_6" kp="40.0" ctrlrange="-0.5 0.5"/>
    <position name="muscle_7_DL" joint="hinge_7" kp="40.0" ctrlrange="-0.5 0.5"/>
    <position name="muscle_7_DR" joint="hinge_7" kp="40.0" ctrlrange="-0.5 0.5"/>
    <position name="muscle_7_VL" joint="hinge_7" kp="40.0" ctrlrange="-0.5 0.5"/>
    <position name="muscle_7_VR" joint="hinge_7" kp="40.0" ctrlrange="-0.5 0.5"/>
    <position name="muscle_8_DL" joint="hinge_8" kp="40.0" ctrlrange="-0.5 0.5"/>
    <position name="muscle_8_DR" joint="hinge_8" kp="40.0" ctrlrange="-0.5 0.5"/>
    <position name="muscle_8_VL" joint="hinge_8" kp="40.0" ctrlrange="-0.5 0.5"/>
    <position name="muscle_8_VR" joint="hinge_8" kp="40.0" ctrlrange="-0.5 0.5"/>
    <position name="muscle_9_DL" joint="hinge_9" kp="40.0" ctrlrange="-0.5 0.5"/>
    <position name="muscle_9_DR" joint="hinge_9" kp="40.0" ctrlrange="-0.5 0.5"/>
    <position name="muscle_9_VL" joint="hinge_9" kp="40.0" ctrlrange="-0.5 0.5"/>
    <position name="muscle_9_VR" joint="hinge_9" kp="40.0" ctrlrange="-0.5 0.5"/>
    <position name="muscle_10_DL" joint="hinge_10" kp="40.0" ctrlrange="-0.5 0.5"/>
    <position name="muscle_10_DR" joint="hinge_10" kp="40.0" ctrlrange="-0.5 0.5"/>
    <position name="muscle_10_VL" joint="hinge_10" kp="40.0" ctrlrange="-0.5 0.5"/>
    <position name="muscle_10_VR" joint="hinge_10" kp="40.0" ctrlrange="-0.5 0.5"/>
    <position name="muscle_11_DL" joint="hinge_11" kp="40.0" ctrlrange="-0.5 0.5"/>
    <position name="muscle_11_DR" joint="hinge_11" kp="40.0" ctrlrange="-0.5 0.5"/>
    <position name="muscle_11_VL" joint="hinge_11" kp="40.0" ctrlrange="-0.5 0.5"/>
    <position name="muscle_11_VR" joint="hinge_11" kp="40.0" ctrlrange="-0.5 0.5"/>
    <position name="muscle_12_DL" joint="hinge_12" kp="40.0" ctrlrange="-0.5 0.5"/>
    <position name="muscle_12_DR" joint="hinge_12" kp="40.0" ctrlrange="-0.5 0.5"/>
    <position name="muscle_12_VL" joint="hinge_12" kp="40.0" ctrlrange="-0.5 0.5"/>
    <position name="muscle_12_VR" joint="hinge_12" kp="40.0" ctrlrange="-0.5 0.5"/>
    <position name="muscle_13_DL" joint="hinge_13" kp="40.0" ctrlrange="-0.5 0.5"/>
    <position name="muscle_13_DR" joint="hinge_13" kp="40.0" ctrlrange="-0.5 0.5"/>
    <position name="muscle_13_VL" joint="hinge_13" kp="40.0" ctrlrange="-0.5 0.5"/>
    <position name="muscle_13_VR" joint="hinge_13" kp="40.0" ctrlrange="-0.5 0.5"/>
    <position name="muscle_14_DL" joint="hinge_14" kp="40.0" ctrlrange="-0.5 0.5"/>
    <position name="muscle_14_DR" joint="hinge_14" kp="40.0" ctrlrange="-0.5 0.5"/>
    <position name="muscle_14_VL" joint="hinge_14" kp="40.0" ctrlrange="-0.5 0.5"/>
    <position name="muscle_14_VR" joint="hinge_14" kp="40.0" ctrlrange="-0.5 0.5"/>
    <position name="muscle_15_DL" joint="hinge_15" kp="40.0" ctrlrange="-0.5 0.5"/>
    <position name="muscle_15_DR" joint="hinge_15" kp="40.0" ctrlrange="-0.5 0.5"/>
    <position name="muscle_15_VL" joint="hinge_15" kp="40.0" ctrlrange="-0.5 0.5"/>
    <position name="muscle_15_VR" joint="hinge_15" kp="40.0" ctrlrange="-0.5 0.5"/>
    <position name="muscle_16_DL" joint="hinge_16" kp="40.0" ctrlrange="-0.5 0.5"/>
    <position name="muscle_16_DR" joint="hinge_16" kp="40.0" ctrlrange="-0.5 0.5"/>
    <position name="muscle_16_VL" joint="hinge_16" kp="40.0" ctrlrange="-0.5 0.5"/>
    <position name="muscle_16_VR" joint="hinge_16" kp="40.0" ctrlrange="-0.5 0.5"/>
    <position name="muscle_17_DL" joint="hinge_17" kp="40.0" ctrlrange="-0.5 0.5"/>
    <position name="muscle_17_DR" joint="hinge_17" kp="40.0" ctrlrange="-0.5 0.5"/>
    <position name="muscle_17_VL" joint="hinge_17" kp="40.0" ctrlrange="-0.5 0.5"/>
    <position name="muscle_17_VR" joint="hinge_17" kp="40.0" ctrlrange="-0.5 0.5"/>
    <position name="muscle_18_DL" joint="hinge_18" kp="40.0" ctrlrange="-0.5 0.5"/>
    <position name="muscle_18_DR" joint="hinge_18" kp="40.0" ctrlrange="-0.5 0.5"/>
    <position name="muscle_18_VL" joint="hinge_18" kp="40.0" ctrlrange="-0.5 0.5"/>
    <position name="muscle_18_VR" joint="hinge_18" kp="40.0" ctrlrange="-0.5 0.5"/>
    <position name="muscle_19_DL" joint="hinge_19" kp="40.0" ctrlrange="-0.5 0.5"/>
    <position name="muscle_19_DR" joint="hinge_19" kp="40.0" ctrlrange="-0.5 0.5"/>
    <position name="muscle_19_VL" joint="hinge_19" kp="40.0" ctrlrange="-0.5 0.5"/>
    <position name="muscle_19_VR" joint="hinge_19" kp="40.0" ctrlrange="-0.5 0.5"/>
  </actuator>
</mujoco>
