<!-- Generated by scripts/build_wormbody.py. Edit the script, not this file. -->
<mujoco model="c_elegans_wormbody">
  <compiler angle="radian" autolimits="true"/>
  <option timestep="0.0005" integrator="implicitfast" viscosity="1.0e-3" density="1000"/>
  <visual>
    <headlight diffuse="0.8 0.8 0.8" ambient="0.3 0.3 0.3" specular="0.2 0.2 0.2"/>
    <global offwidth="1200" offheight="800"/>
  </visual>
  <default>
    <joint damping="0.001" stiffness="0.0" limited="true" range="-0.5 0.5"/>
    <geom density="1000" friction="0.5 0.1 0.01"/>
    <motor ctrllimited="true" ctrlrange="-1.0 1.0" gear="0.001"/>
  </default>
  <worldbody>
    <geom name="substrate" type="plane" size="0.01 0.01 0.001" rgba="0.95 0.92 0.82 1"/>
    <light name="overhead" pos="0 0 0.02" dir="0 0 -1" diffuse="0.8 0.8 0.8"/>
    <body name="segment_0" pos="0 0 0.0800000" euler="0 0 0">
      <freejoint name="root"/>
      <geom name="geom_0" type="capsule" fromto="0 0 0 0.0500000 0 0" size="0.0400000" rgba="0.25 0.38 0.25 1"/>
        <body name="segment_1" pos="0.0500000 0 0">
          <joint name="hinge_1" type="hinge" axis="0 0 1"/>
          <geom name="geom_1" type="capsule" fromto="0 0 0 0.0500000 0 0" size="0.0400000" rgba="0.35 0.48 0.32 1"/>
          <body name="segment_2" pos="0.0500000 0 0">
            <joint name="hinge_2" type="hinge" axis="0 0 1"/>
            <geom name="geom_2" type="capsule" fromto="0 0 0 0.0500000 0 0" size="0.0400000" rgba="0.35 0.48 0.32 1"/>
            <body name="segment_3" pos="0.0500000 0 0">
              <joint name="hinge_3" type="hinge" axis="0 0 1"/>
              <geom name="geom_3" type="capsule" fromto="0 0 0 0.0500000 0 0" size="0.0400000" rgba="0.35 0.48 0.32 1"/>
              <body name="segment_4" pos="0.0500000 0 0">
                <joint name="hinge_4" type="hinge" axis="0 0 1"/>
                <geom name="geom_4" type="capsule" fromto="0 0 0 0.0500000 0 0" size="0.0400000" rgba="0.35 0.48 0.32 1"/>
                <body name="segment_5" pos="0.0500000 0 0">
                  <joint name="hinge_5" type="hinge" axis="0 0 1"/>
                  <geom name="geom_5" type="capsule" fromto="0 0 0 0.0500000 0 0" size="0.0400000" rgba="0.35 0.48 0.32 1"/>
                  <body name="segment_6" pos="0.0500000 0 0">
                    <joint name="hinge_6" type="hinge" axis="0 0 1"/>
                    <geom name="geom_6" type="capsule" fromto="0 0 0 0.0500000 0 0" size="0.0400000" rgba="0.35 0.48 0.32 1"/>
                    <body name="segment_7" pos="0.0500000 0 0">
                      <joint name="hinge_7" type="hinge" axis="0 0 1"/>
                      <geom name="geom_7" type="capsule" fromto="0 0 0 0.0500000 0 0" size="0.0400000" rgba="0.35 0.48 0.32 1"/>
                      <body name="segment_8" pos="0.0500000 0 0">
                        <joint name="hinge_8" type="hinge" axis="0 0 1"/>
                        <geom name="geom_8" type="capsule" fromto="0 0 0 0.0500000 0 0" size="0.0400000" rgba="0.35 0.48 0.32 1"/>
                        <body name="segment_9" pos="0.0500000 0 0">
                          <joint name="hinge_9" type="hinge" axis="0 0 1"/>
                          <geom name="geom_9" type="capsule" fromto="0 0 0 0.0500000 0 0" size="0.0400000" rgba="0.35 0.48 0.32 1"/>
                          <body name="segment_10" pos="0.0500000 0 0">
                            <joint name="hinge_10" type="hinge" axis="0 0 1"/>
                            <geom name="geom_10" type="capsule" fromto="0 0 0 0.0500000 0 0" size="0.0400000" rgba="0.35 0.48 0.32 1"/>
                            <body name="segment_11" pos="0.0500000 0 0">
                              <joint name="hinge_11" type="hinge" axis="0 0 1"/>
                              <geom name="geom_11" type="capsule" fromto="0 0 0 0.0500000 0 0" size="0.0400000" rgba="0.35 0.48 0.32 1"/>
                              <body name="segment_12" pos="0.0500000 0 0">
                                <joint name="hinge_12" type="hinge" axis="0 0 1"/>
                                <geom name="geom_12" type="capsule" fromto="0 0 0 0.0500000 0 0" size="0.0400000" rgba="0.35 0.48 0.32 1"/>
                                <body name="segment_13" pos="0.0500000 0 0">
                                  <joint name="hinge_13" type="hinge" axis="0 0 1"/>
                                  <geom name="geom_13" type="capsule" fromto="0 0 0 0.0500000 0 0" size="0.0400000" rgba="0.35 0.48 0.32 1"/>
                                  <body name="segment_14" pos="0.0500000 0 0">
                                    <joint name="hinge_14" type="hinge" axis="0 0 1"/>
                                    <geom name="geom_14" type="capsule" fromto="0 0 0 0.0500000 0 0" size="0.0400000" rgba="0.35 0.48 0.32 1"/>
                                    <body name="segment_15" pos="0.0500000 0 0">
                                      <joint name="hinge_15" type="hinge" axis="0 0 1"/>
                                      <geom name="geom_15" type="capsule" fromto="0 0 0 0.0500000 0 0" size="0.0400000" rgba="0.35 0.48 0.32 1"/>
                                      <body name="segment_16" pos="0.0500000 0 0">
                                        <joint name="hinge_16" type="hinge" axis="0 0 1"/>
                                        <geom name="geom_16" type="capsule" fromto="0 0 0 0.0500000 0 0" size="0.0400000" rgba="0.35 0.48 0.32 1"/>
                                        <body name="segment_17" pos="0.0500000 0 0">
                                          <joint name="hinge_17" type="hinge" axis="0 0 1"/>
                                          <geom name="geom_17" type="capsule" fromto="0 0 0 0.0500000 0 0" size="0.0400000" rgba="0.35 0.48 0.32 1"/>
                                          <body name="segment_18" pos="0.0500000 0 0">
                                            <joint name="hinge_18" type="hinge" axis="0 0 1"/>
                                            <geom name="geom_18" type="capsule" fromto="0 0 0 0.0500000 0 0" size="0.0400000" rgba="0.35 0.48 0.32 1"/>
                                            <body name="segment_19" pos="0.0500000 0 0">
                                              <joint name="hinge_19" type="hinge" axis="0 0 1"/>
                                              <geom name="geom_19" type="capsule" fromto="0 0 0 0.0500000 0 0" size="0.0400000" rgba="0.35 0.48 0.32 1"/>
                                            </body>
                                          </body>
                                        </body>
                                      </body>
                                    </body>
                                  </body>
                                </body>
                              </body>
                            </body>
                          </body>
                        </body>
                      </body>
                    </body>
                  </body>
                </body>
              </body>
            </body>
          </body>
        </body>
      </body>
  </worldbody>
  <actuator>
    <motor name="muscle_1" joint="hinge_1"/>
    <motor name="muscle_2" joint="hinge_2"/>
    <motor name="muscle_3" joint="hinge_3"/>
    <motor name="muscle_4" joint="hinge_4"/>
    <motor name="muscle_5" joint="hinge_5"/>
    <motor name="muscle_6" joint="hinge_6"/>
    <motor name="muscle_7" joint="hinge_7"/>
    <motor name="muscle_8" joint="hinge_8"/>
    <motor name="muscle_9" joint="hinge_9"/>
    <motor name="muscle_10" joint="hinge_10"/>
    <motor name="muscle_11" joint="hinge_11"/>
    <motor name="muscle_12" joint="hinge_12"/>
    <motor name="muscle_13" joint="hinge_13"/>
    <motor name="muscle_14" joint="hinge_14"/>
    <motor name="muscle_15" joint="hinge_15"/>
    <motor name="muscle_16" joint="hinge_16"/>
    <motor name="muscle_17" joint="hinge_17"/>
    <motor name="muscle_18" joint="hinge_18"/>
    <motor name="muscle_19" joint="hinge_19"/>
  </actuator>
  <sensor>
    <framepos name="pos_segment_0" objtype="body" objname="segment_0"/>
    <framepos name="pos_segment_1" objtype="body" objname="segment_1"/>
    <framepos name="pos_segment_2" objtype="body" objname="segment_2"/>
    <framepos name="pos_segment_3" objtype="body" objname="segment_3"/>
    <framepos name="pos_segment_4" objtype="body" objname="segment_4"/>
    <framepos name="pos_segment_5" objtype="body" objname="segment_5"/>
    <framepos name="pos_segment_6" objtype="body" objname="segment_6"/>
    <framepos name="pos_segment_7" objtype="body" objname="segment_7"/>
    <framepos name="pos_segment_8" objtype="body" objname="segment_8"/>
    <framepos name="pos_segment_9" objtype="body" objname="segment_9"/>
    <framepos name="pos_segment_10" objtype="body" objname="segment_10"/>
    <framepos name="pos_segment_11" objtype="body" objname="segment_11"/>
    <framepos name="pos_segment_12" objtype="body" objname="segment_12"/>
    <framepos name="pos_segment_13" objtype="body" objname="segment_13"/>
    <framepos name="pos_segment_14" objtype="body" objname="segment_14"/>
    <framepos name="pos_segment_15" objtype="body" objname="segment_15"/>
    <framepos name="pos_segment_16" objtype="body" objname="segment_16"/>
    <framepos name="pos_segment_17" objtype="body" objname="segment_17"/>
    <framepos name="pos_segment_18" objtype="body" objname="segment_18"/>
    <framepos name="pos_segment_19" objtype="body" objname="segment_19"/>
  </sensor>
</mujoco>
